Workbook

Sheet Sheet4
A1: year | B1: Residents | C1: Non-residetns | D1: Males | E1: Females | F1: male(0+) | G1: male(1+) | H1: male(2+) | I1: male(3+) | J1: male(4+) | K1: male(5+) | L1: male(6+) | M1: male(7+) | N1: male(8+) | O1: male(9+) | P1: male(10+) | Q1: male(11+) | R1: male(12+) | S1: male(13+) | T1: male(14+) | U1: male(15+) | V1: male(16+) | W1: male(17+) | X1: male(18+) | Y1: male(19+) | Z1: male(20+) | AA1: male(21+) | AB1: male(22+) | AC1: male(23+) | AD1: male(24+) | AE1: male(25+) | AF1: male(26+) | AG1: male(27+) | AH1: male(28+) | AI1: male(29+) | AJ1: male(30+) | AK1: male(31+) | AL1: male(32+) | AM1: male(33+) | AN1: male(34+) | AO1: male(35+) | AP1: male(36+) | AQ1: male(37+) | AR1: male(38+) | AS1: male(39+) | AT1: male(40+) | AU1: male(41+) | AV1: male(42+) | AW1: male(43+) | AX1: male(44+) | AY1: male(45+) | AZ1: male(46+) | BA1: male(47+) | BB1: male(48+) | BC1: male(49+) | BD1: male(50+) | BE1: male(51+) | BF1: male(52+) | BG1: male(53+) | BH1: male(54+) | BI1: male(55+) | BJ1: male(56+) | BK1: male(57+) | BL1: male(58+) | BM1: male(59+) | BN1: male(60+) | BO1: male(61+) | BP1: male(62+) | BQ1: male(63+) | BR1: male(64+) | BS1: male(65+) | BT1: male(66+) | BU1: male(67+) | BV1: male(68+) | BW1: male(69+) | BX1: male(70+) | BY1: male(71+) | BZ1: male(72+) | CA1: male(73+) | CB1: male(74+) | CC1: male(75+) | CD1: male(76+) | CE1: male(77+) | CF1: male(78+) | CG1: male(79+) | CH1: male(80+) | CI1: male(81+) | CJ1: male(82+) | CK1: male(83+) | CL1: male(84+) | CM1: male(85+) | CN1: male(86+) | CO1: male(87+) | CP1: male(88+) | CQ1: male(89+) | CR1: male(90+) | CS1: male(91+) | CT1: male(92+) | CU1: male(93+) | CV1: male(94+) | CW1: male(95+) | CX1: male(96+) | CY1: male(97+) | CZ1: male(98+) | DA1: male(99+) | DB1: maleAverageAge | DC1: female(0+) | DD1: female(1+) | DE1: female(2+) | DF1: female(3+) | DG1: female(4+) | DH1: female(5+) | DI1: female(6+) | DJ1: female(7+) | DK1: female(8+) | DL1: female(9+) | DM1: female(10+) | DN1: female(11+) | DO1: female(12+) | DP1: female(13+) | DQ1: female(14+) | DR1: female(15+) | DS1: female(16+) | DT1: female(17+) | DU1: female(18+) | DV1: female(19+) | DW1: female(20+) | DX1: female(21+) | DY1: female(22+) | DZ1: female(23+) | EA1: female(24+) | EB1: female(25+) | EC1: female(26+) | ED1: female(27+) | EE1: female(28+) | EF1: female(29+) | EG1: female(30+) | EH1: female(31+) | EI1: female(32+) | EJ1: female(33+) | EK1: female(34+) | EL1: female(35+) | EM1: female(36+) | EN1: female(37+) | EO1: female(38+) | EP1: female(39+) | EQ1: female(40+) | ER1: female(41+) | ES1: female(42+) | ET1: female(43+) | EU1: female(44+) | EV1: female(45+) | EW1: female(46+) | EX1: female(47+) | EY1: female(48+) | EZ1: female(49+) | FA1: female(50+) | FB1: female(51+) | FC1: female(52+) | FD1: female(53+) | FE1: female(54+) | FF1: female(55+) | FG1: female(56+) | FH1: female(57+) | FI1: female(58+) | FJ1: female(59+) | FK1: female(60+) | FL1: female(61+) | FM1: female(62+) | FN1: female(63+) | FO1: female(64+) | FP1: female(65+) | FQ1: female(66+) | FR1: female(67+) | FS1: female(68+) | FT1: female(69+) | FU1: female(70+) | FV1: female(71+) | FW1: female(72+) | FX1: female(73+) | FY1: female(74+) | FZ1: female(75+) | GA1: female(76+) | GB1: female(77+) | GC1: female(78+) | GD1: female(79+) | GE1: female(80+) | GF1: female(81+) | GG1: female(82+) | GH1: female(83+) | GI1: female(84+) | GJ1: female(85+) | GK1: female(86+) | GL1: female(87+) | GM1: female(88+) | GN1: female(89+) | GO1: female(90+) | GP1: female(91+) | GQ1: female(92+) | GR1: female(93+) | GS1: female(94+) | GT1: female(95+) | GU1: female(96+) | GV1: female(97+) | GW1: female(98+) | GX1: female(99+) | GY1: femaleAverageAge | GZ1: male(20;29)divorced | HA1: male(30;39)divorced | HB1: male(40;49)divorced | HC1: male(50;59)divorced | HD1: male(60;69)divorced | HE1: male(70;79)divorced | HF1: male(80+)divorced | HG1: female(20;29)divorced | HH1: female(30;39)divorced | HI1: female(40;49)divorced | HJ1: female(50;59)divorced | HK1: female(60;69)divorced | HL1: female(70;79)divorced | HM1: female(80+)divorced | HN1: male(20;29)married | HO1: male(30;39)married | HP1: male(40;49)married | HQ1: male(50;59)married | HR1: male(60;69)married | HS1: male(70;79)married | HT1: male(80+)married | HU1: female(20;29)married | HV1: female(30;39)married | HW1: female(40;49)married | HX1: female(50;59)married | HY1: female(60;69)married | HZ1: female(70;79)married | IA1: female(80+)married | IB1: male(20;29)single | IC1: male(30;39)single | ID1: male(40;49)single | IE1: male(50;59)single | IF1: male(60;69)single | IG1: male(70;79)single | IH1: male(80+)single | II1: female(20;29)single | IJ1: female(30;39)single | IK1: female(40;49)single | IL1: female(50;59)single | IM1: female(60;69)single | IN1: female(70;79)single | IO1: female(80+)single | IP1: male(20;29)widowed | IQ1: male(30;39)widowed | IR1: male(40;49)widowed | IS1: male(50;59)widowed | IT1: male(60;69)widowed | IU1: male(70;79)widowed | IV1: male(80+)widowed | IW1: female(20;29)widowed | IX1: female(30;39)widowed | IY1: female(40;49)widowed | IZ1: female(50;59)widowed | JA1: female(60;69)widowed | JB1: female(70;79)widowed | JC1: female(80+)widowed
A2: 1990 | B2: 2735862 | C2: 246389 | D2: 1386293 | E2: 1349569 | F2: 23192 | G2: 23157 | H2: 23042 | I2: 22813 | J2: 22469 | K2: 22076 | L2: 21715 | M2: 21435 | N2: 21220 | O2: 21031 | P2: 20863 | Q2: 20764 | R2: 20818 | S2: 21078 | T2: 21527 | U2: 22056 | V2: 22547 | W2: 22936 | X2: 23249 | Y2: 23537 | Z2: 23837 | AA2: 24181 | AB2: 24662 | AC2: 25386 | AD2: 26381 | AE2: 27487 | AF2: 28474 | AG2: 29174 | AH2: 29605 | AI2: 29875 | AJ2: 30063 | AK2: 30136 | AL2: 29976 | AM2: 29494 | AN2: 28708 | AO2: 27779 | AP2: 26868 | AQ2: 26011 | AR2: 25102 | AS2: 24051 | AT2: 22910 | AU2: 21784 | AV2: 20653 | AW2: 19354 | AX2: 17778 | AY2: 16087 | AZ2: 14597 | BA2: 13552 | BB2: 12933 | BC2: 12574 | BD2: 12312 | BE2: 12078 | BF2: 11829 | BG2: 11527 | BH2: 11149 | BI2: 10734 | BJ2: 10342 | BK2: 9996 | BL2: 9659 | BM2: 9293 | BN2: 8906 | BO2: 8531 | BP2: 8169 | BQ2: 7771 | BR2: 7301 | BS2: 6796 | BT2: 6325 | BU2: 5927 | BV2: 5563 | BW2: 5186 | BX2: 4799 | BY2: 4443 | BZ2: 4142 | CA2: 3869 | CB2: 3588 | CC2: 3297 | CD2: 3024 | CE2: 2776 | CF2: 2524 | CG2: 2243 | CH2: 1946 | CI2: 1675 | CJ2: 1458 | CK2: 1278 | CL2: 1107 | CM2: 940 | CN2: 797 | CO2: 702 | CP2: 654 | CQ2: 640 | CR2: 0 | CS2: 0 | CT2: 0 | CU2: 0 | CV2: 0 | CW2: 0 | CX2: 0 | CY2: 0 | CZ2: 0 | DA2: 0 | DB2: 30.192 | DC2: 21607 | DD2: 21584 | DE2: 21494 | DF2: 21269 | DG2: 20908 | DH2: 20480 | DI2: 20112 | DJ2: 19856 | DK2: 19689 | DL2: 19545 | DM2: 19400 | DN2: 19309 | DO2: 19354 | DP2: 19626 | DQ2: 20103 | DR2: 20679 | DS2: 21187 | DT2: 21581 | DU2: 21932 | DV2: 22329 | DW2: 22766 | DX2: 23196 | DY2: 23681 | DZ2: 24410 | EA2: 25452 | EB2: 26663 | EC2: 27690 | ED2: 28356 | EE2: 28685 | EF2: 28868 | EG2: 29008 | EH2: 29076 | EI2: 28946 | EJ2: 28467 | EK2: 27660 | EL2: 26692 | EM2: 25819 | EN2: 25073 | EO2: 24278 | EP2: 23280 | EQ2: 22156 | ER2: 21116 | ES2: 20149 | ET2: 18975 | EU2: 17416 | EV2: 15635 | EW2: 14123 | EX2: 13135 | EY2: 12635 | EZ2: 12341 | FA2: 12102 | FB2: 11881 | FC2: 11673 | FD2: 11416 | FE2: 11073 | FF2: 10679 | FG2: 10328 | FH2: 10039 | FI2: 9753 | FJ2: 9405 | FK2: 9018 | FL2: 8663 | FM2: 8346 | FN2: 7982 | FO2: 7511 | FP2: 6975 | FQ2: 6509 | FR2: 6168 | FS2: 5908 | FT2: 5644 | FU2: 5364 | FV2: 5113 | FW2: 4905 | FX2: 4696 | FY2: 4440 | FZ2: 4154 | GA2: 3893 | GB2: 3664 | GC2: 3408 | GD2: 3080 | GE2: 2707 | GF2: 2384 | GG2: 2148 | GH2: 1970 | GI2: 1792 | GJ2: 1602 | GK2: 1443 | GL2: 1344 | GM2: 1304 | GN2: 1294 | GO2: 0 | GP2: 0 | GQ2: 0 | GR2: 0 | GS2: 0 | GT2: 0 | GU2: 0 | GV2: 0 | GW2: 0 | GX2: 0 | GY2: 31.205502 | GZ2: 816 | HA2: 3601 | HB2: 3000 | HC2: 1701 | HD2: 702 | HE2: 233 | HF2: 66 | HG2: 2000 | HH2: 6298 | HI2: 5302 | HJ2: 2700 | HK2: 1001 | HL2: 314 | HM2: 86 | HN2: 73837 | HO2: 198600 | HP2: 144326 | HQ2: 95702 | HR2: 57728 | HS2: 23376 | HT2: 6979 | HU2: 106260 | HV2: 198600 | HW2: 146885 | HX2: 87249 | HY2: 41223 | HZ2: 12862 | IA2: 6743 | IB2: 193609 | IC2: 74286 | ID2: 23097 | IE2: 8016 | IF2: 5144 | IG2: 3172 | IH2: 1076 | II2: 150507 | IJ2: 60301 | IK2: 8293 | IL2: 0 | IM2: 0 | IN2: 0 | IO2: 0 | IP2: 800 | IQ2: 1701 | IR2: 1799 | IS2: 3500 | IT2: 6901 | IU2: 7924 | IV2: 3076 | IW2: 1000 | IX2: 3100 | IY2: 7201 | IZ2: 18400 | JA2: 30500 | JB2: 29541 | JC2: 11159
A3: 1991 | B3: 2790350 | C3: 310676 | D3: 1411319 | E3: 1379031 | F3: 0 | G3: 48314 | H3: 23316 | I3: 23185 | J3: 22953 | K3: 22610 | L3: 22198 | M3: 21841 | N3: 21561 | O3: 21380 | P3: 21169 | Q3: 20995 | R3: 20886 | S3: 20963 | T3: 21191 | U3: 21627 | V3: 22181 | W3: 22671 | X3: 23060 | Y3: 23376 | Z3: 23678 | AA3: 23946 | AB3: 24304 | AC3: 24806 | AD3: 25522 | AE3: 26520 | AF3: 27628 | AG3: 28630 | AH3: 29330 | AI3: 29751 | AJ3: 30065 | AK3: 30210 | AL3: 30285 | AM3: 30158 | AN3: 29643 | AO3: 28885 | AP3: 27892 | AQ3: 26951 | AR3: 26105 | AS3: 25200 | AT3: 24162 | AU3: 22970 | AV3: 21858 | AW3: 20709 | AX3: 19425 | AY3: 17847 | AZ3: 16108 | BA3: 14602 | BB3: 13565 | BC3: 12959 | BD3: 12588 | BE3: 12283 | BF3: 12056 | BG3: 11806 | BH3: 11506 | BI3: 11119 | BJ3: 10644 | BK3: 10265 | BL3: 9914 | BM3: 9569 | BN3: 9228 | BO3: 8737 | BP3: 8371 | BQ3: 8007 | BR3: 7615 | BS3: 7176 | BT3: 6586 | BU3: 6119 | BV3: 5768 | BW3: 5369 | BX3: 5014 | BY3: 4557 | BZ3: 4204 | CA3: 3906 | CB3: 3667 | CC3: 3423 | CD3: 3039 | CE3: 2787 | CF3: 2565 | CG3: 2314 | CH3: 2072 | CI3: 1745 | CJ3: 1515 | CK3: 1292 | CL3: 1129 | CM3: 983 | CN3: 804 | CO3: 680 | CP3: 608 | CQ3: 553 | CR3: 545 | CS3: 0 | CT3: 0 | CU3: 0 | CV3: 0 | CW3: 0 | CX3: 0 | CY3: 0 | CZ3: 0 | DA3: 0 | DB3: 30.449647 | DC3: 0 | DD3: 48797 | DE3: 21744 | DF3: 21665 | DG3: 21428 | DH3: 21070 | DI3: 20658 | DJ3: 20247 | DK3: 19998 | DL3: 19820 | DM3: 19673 | DN3: 19523 | DO3: 19447 | DP3: 19452 | DQ3: 19761 | DR3: 20242 | DS3: 20822 | DT3: 21318 | DU3: 21730 | DV3: 22103 | DW3: 22498 | DX3: 22933 | DY3: 23370 | DZ3: 23850 | EA3: 24586 | EB3: 25615 | EC3: 26848 | ED3: 27864 | EE3: 28525 | EF3: 28877 | EG3: 29039 | EH3: 29192 | EI3: 29264 | EJ3: 29133 | EK3: 28631 | EL3: 27843 | EM3: 26794 | EN3: 25913 | EO3: 25184 | EP3: 24370 | EQ3: 23364 | ER3: 22223 | ES3: 21189 | ET3: 20227 | EU3: 19056 | EV3: 17519 | EW3: 15702 | EX3: 14188 | EY3: 13184 | EZ3: 12685 | FA3: 12403 | FB3: 12117 | FC3: 11903 | FD3: 11689 | FE3: 11433 | FF3: 11098 | FG3: 10659 | FH3: 10308 | FI3: 10010 | FJ3: 9735 | FK3: 9403 | FL3: 8982 | FM3: 8624 | FN3: 8277 | FO3: 7902 | FP3: 7442 | FQ3: 6891 | FR3: 6398 | FS3: 6074 | FT3: 5809 | FU3: 5554 | FV3: 5198 | FW3: 4956 | FX3: 4737 | FY3: 4532 | FZ3: 4297 | GA3: 3955 | GB3: 3687 | GC3: 3474 | GD3: 3232 | GE3: 2911 | GF3: 2489 | GG3: 2180 | GH3: 1994 | GI3: 1821 | GJ3: 1652 | GK3: 1393 | GL3: 1252 | GM3: 1177 | GN3: 1111 | GO3: 1108 | GP3: 0 | GQ3: 0 | GR3: 0 | GS3: 0 | GT3: 0 | GU3: 0 | GV3: 0 | GW3: 0 | GX3: 0 | GY3: 31.404213 | GZ3: 1457 | HA3: 4704 | HB3: 3750 | HC3: 1972 | HD3: 888 | HE3: 301 | HF3: 77 | HG3: 2671 | HH3: 7720 | HI3: 6304 | HJ3: 3143 | HK3: 1201 | HL3: 367 | HM3: 101 | HN3: 78170 | HO3: 197067 | HP3: 153824 | HQ3: 98970 | HR3: 58357 | HS3: 23912 | HT3: 7124 | HU3: 93521 | HV3: 187749 | HW3: 155494 | HX3: 90404 | HY3: 44872 | HZ3: 13318 | IA3: 6393 | IB3: 183818 | IC3: 81972 | ID3: 24679 | IE3: 7025 | IF3: 6002 | IG3: 2538 | IH3: 1446 | II3: 157523 | IJ3: 76794 | IK3: 9717 | IL3: 1 | IM3: 0 | IN3: 1 | IO3: 0 | IP3: 670 | IQ3: 1651 | IR3: 1952 | IS3: 3783 | IT3: 7729 | IU3: 8725 | IV3: 3279 | IW3: 1251 | IX3: 3100 | IY3: 7822 | IZ3: 17807 | JA3: 29729 | JB3: 29936 | JC3: 12594
A4: 1992 | B4: 2849225 | C4: 375760 | D4: 1438645 | E4: 1410580 | F4: 0 | G4: 25143 | H4: 48488 | I4: 23521 | J4: 23395 | K4: 23135 | L4: 22794 | M4: 22387 | N4: 22034 | O4: 21739 | P4: 21560 | Q4: 21366 | R4: 21188 | S4: 21058 | T4: 21163 | U4: 21381 | V4: 21818 | W4: 22350 | X4: 22850 | Y4: 23250 | Z4: 23540 | AA4: 23850 | AB4: 24124 | AC4: 24485 | AD4: 25015 | AE4: 25721 | AF4: 26743 | AG4: 27866 | AH4: 28881 | AI4: 29589 | AJ4: 29997 | AK4: 30303 | AL4: 30466 | AM4: 30536 | AN4: 30365 | AO4: 29899 | AP4: 28993 | AQ4: 27958 | AR4: 27053 | AS4: 26185 | AT4: 25289 | AU4: 24241 | AV4: 23046 | AW4: 21932 | AX4: 20751 | AY4: 19452 | AZ4: 17870 | BA4: 16116 | BB4: 14608 | BC4: 13556 | BD4: 12993 | BE4: 12595 | BF4: 12255 | BG4: 12024 | BH4: 11767 | BI4: 11490 | BJ4: 11008 | BK4: 10563 | BL4: 10176 | BM4: 9833 | BN4: 9520 | BO4: 9070 | BP4: 8595 | BQ4: 8247 | BR4: 7877 | BS4: 7472 | BT4: 6944 | BU4: 6377 | BV4: 5957 | BW4: 5617 | BX4: 5228 | BY4: 4788 | BZ4: 4325 | CA4: 4009 | CB4: 3729 | CC4: 3519 | CD4: 3176 | CE4: 2846 | CF4: 2578 | CG4: 2352 | CH4: 2162 | CI4: 1864 | CJ4: 1557 | CK4: 1364 | CL4: 1145 | CM4: 1010 | CN4: 839 | CO4: 694 | CP4: 582 | CQ4: 513 | CR4: 484 | CS4: 451 | CT4: 0 | CU4: 0 | CV4: 0 | CW4: 0 | CX4: 0 | CY4: 0 | CZ4: 0 | DA4: 0 | DB4: 30.704028 | DC4: 0 | DD4: 27510 | DE4: 48961 | DF4: 21912 | DG4: 21841 | DH4: 21605 | DI4: 21249 | DJ4: 20829 | DK4: 20436 | DL4: 20172 | DM4: 19974 | DN4: 19816 | DO4: 19671 | DP4: 19605 | DQ4: 19620 | DR4: 19922 | DS4: 20404 | DT4: 20993 | DU4: 21504 | DV4: 21896 | DW4: 22298 | DX4: 22706 | DY4: 23133 | DZ4: 23569 | EA4: 24036 | EB4: 24802 | EC4: 25805 | ED4: 27053 | EE4: 28067 | EF4: 28726 | EG4: 29097 | EH4: 29287 | EI4: 29446 | EJ4: 29493 | EK4: 29363 | EL4: 28874 | EM4: 27984 | EN4: 26907 | EO4: 26022 | EP4: 25298 | EQ4: 24503 | ER4: 23478 | ES4: 22310 | ET4: 21290 | EU4: 20308 | EV4: 19154 | EW4: 17617 | EX4: 15748 | EY4: 14248 | EZ4: 13222 | FA4: 12747 | FB4: 12446 | FC4: 12169 | FD4: 11940 | FE4: 11733 | FF4: 11464 | FG4: 11078 | FH4: 10686 | FI4: 10293 | FJ4: 10024 | FK4: 9744 | FL4: 9356 | FM4: 8933 | FN4: 8564 | FO4: 8245 | FP4: 7871 | FQ4: 7340 | FR4: 6800 | FS4: 6312 | FT4: 6011 | FU4: 5721 | FV4: 5421 | FW4: 5047 | FX4: 4808 | FY4: 4616 | FZ4: 4408 | GA4: 4118 | GB4: 3774 | GC4: 3517 | GD4: 3301 | GE4: 3109 | GF4: 2700 | GG4: 2311 | GH4: 2010 | GI4: 1839 | GJ4: 1670 | GK4: 1416 | GL4: 1220 | GM4: 1103 | GN4: 989 | GO4: 989 | GP4: 973 | GQ4: 0 | GR4: 0 | GS4: 0 | GT4: 0 | GU4: 0 | GV4: 0 | GW4: 0 | GX4: 0 | GY4: 31.614127 | GZ4: 2052 | HA4: 5602 | HB4: 4633 | HC4: 2318 | HD4: 1069 | HE4: 383 | HF4: 90 | HG4: 3160 | HH4: 8944 | HI4: 7473 | HJ4: 3639 | HK4: 1435 | HL4: 450 | HM4: 111 | HN4: 80638 | HO4: 196635 | HP4: 163239 | HQ4: 102147 | HR4: 59816 | HS4: 24525 | HT4: 7406 | HU4: 82951 | HV4: 175170 | HW4: 163440 | HX4: 93544 | HY4: 48455 | HZ4: 13993 | IA4: 6295 | IB4: 176588 | IC4: 87965 | ID4: 26900 | IE4: 6261 | IF4: 6634 | IG4: 1955 | IH4: 1756 | II4: 162649 | IJ4: 94661 | IK4: 12481 | IL4: 127 | IM4: 102 | IN4: 64 | IO4: 5 | IP4: 536 | IQ4: 1553 | IR4: 2089 | IS4: 3978 | IT4: 8157 | IU4: 9687 | IV4: 3413 | IW4: 1435 | IX4: 2996 | IY4: 8484 | IZ4: 17270 | JA4: 29184 | JB4: 30224 | JC4: 13918
A5: 1993 | B5: 2910879 | C5: 439052 | D5: 1467789 | E5: 1443090 | F5: 0 | G5: 25221 | H5: 25360 | I5: 48708 | J5: 23780 | K5: 23629 | L5: 23361 | M5: 23047 | N5: 22614 | O5: 22263 | P5: 21994 | Q5: 21794 | R5: 21578 | S5: 21397 | T5: 21292 | U5: 21376 | V5: 21614 | W5: 22050 | X5: 22596 | Y5: 23087 | Z5: 23470 | AA5: 23751 | AB5: 24115 | AC5: 24353 | AD5: 24766 | AE5: 25283 | AF5: 25962 | AG5: 27035 | AH5: 28134 | AI5: 29169 | AJ5: 29868 | AK5: 30317 | AL5: 30596 | AM5: 30789 | AN5: 30849 | AO5: 30696 | AP5: 30038 | AQ5: 29077 | AR5: 28033 | AS5: 27124 | AT5: 26258 | AU5: 25358 | AV5: 24296 | AW5: 23088 | AX5: 22009 | AY5: 20781 | AZ5: 19472 | BA5: 17885 | BB5: 16109 | BC5: 14609 | BD5: 13556 | BE5: 12950 | BF5: 12570 | BG5: 12232 | BH5: 12001 | BI5: 11735 | BJ5: 11408 | BK5: 10930 | BL5: 10460 | BM5: 10113 | BN5: 9759 | BO5: 9397 | BP5: 8934 | BQ5: 8442 | BR5: 8129 | BS5: 7735 | BT5: 7284 | BU5: 6753 | BV5: 6190 | BW5: 5793 | BX5: 5469 | BY5: 5006 | BZ5: 4595 | CA5: 4143 | CB5: 3862 | CC5: 3596 | CD5: 3290 | CE5: 2954 | CF5: 2652 | CG5: 2399 | CH5: 2214 | CI5: 1959 | CJ5: 1666 | CK5: 1395 | CL5: 1221 | CM5: 1020 | CN5: 865 | CO5: 724 | CP5: 600 | CQ5: 492 | CR5: 442 | CS5: 415 | CT5: 388 | CU5: 0 | CV5: 0 | CW5: 0 | CX5: 0 | CY5: 0 | CZ5: 0 | DA5: 0 | DB5: 30.955403 | DC5: 0 | DD5: 27278 | DE5: 27653 | DF5: 49165 | DG5: 22127 | DH5: 22048 | DI5: 21819 | DJ5: 21446 | DK5: 21023 | DL5: 20627 | DM5: 20358 | DN5: 20154 | DO5: 20006 | DP5: 19851 | DQ5: 19805 | DR5: 19799 | DS5: 20083 | DT5: 20589 | DU5: 21180 | DV5: 21694 | DW5: 22111 | DX5: 22508 | DY5: 22892 | DZ5: 23327 | EA5: 23776 | EB5: 24245 | EC5: 25041 | ED5: 26034 | EE5: 27295 | EF5: 28337 | EG5: 28980 | EH5: 29364 | EI5: 29550 | EJ5: 29722 | EK5: 29747 | EL5: 29607 | EM5: 29016 | EN5: 28134 | EO5: 27041 | EP5: 26127 | EQ5: 25434 | ER5: 24609 | ES5: 23599 | ET5: 22405 | EU5: 21386 | EV5: 20392 | EW5: 19233 | EX5: 17687 | EY5: 15837 | EZ5: 14315 | FA5: 13274 | FB5: 12793 | FC5: 12495 | FD5: 12213 | FE5: 11993 | FF5: 11781 | FG5: 11477 | FH5: 11072 | FI5: 10694 | FJ5: 10332 | FK5: 10042 | FL5: 9697 | FM5: 9347 | FN5: 8912 | FO5: 8553 | FP5: 8198 | FQ5: 7781 | FR5: 7249 | FS5: 6717 | FT5: 6242 | FU5: 5941 | FV5: 5598 | FW5: 5319 | FX5: 4920 | FY5: 4701 | FZ5: 4508 | GA5: 4231 | GB5: 3943 | GC5: 3626 | GD5: 3353 | GE5: 3171 | GF5: 2882 | GG5: 2532 | GH5: 2157 | GI5: 1848 | GJ5: 1716 | GK5: 1469 | GL5: 1234 | GM5: 1080 | GN5: 972 | GO5: 863 | GP5: 856 | GQ5: 851 | GR5: 0 | GS5: 0 | GT5: 0 | GU5: 0 | GV5: 0 | GW5: 0 | GX5: 0 | GY5: 31.843842 | GZ5: 2624 | HA5: 6440 | HB5: 5561 | HC5: 2671 | HD5: 1262 | HE5: 467 | HF5: 114 | HG5: 3458 | HH5: 9993 | HI5: 8787 | HJ5: 4185 | HK5: 1705 | HL5: 520 | HM5: 138 | HN5: 81255 | HO5: 197128 | HP5: 172470 | HQ5: 105564 | HR5: 61566 | HS5: 25234 | HT5: 7712 | HU5: 74124 | HV5: 161099 | HW5: 170589 | HX5: 96769 | HY5: 52041 | HZ5: 14948 | IA5: 6265 | IB5: 171716 | IC5: 92398 | ID5: 29652 | IE5: 5625 | IF5: 7159 | IG5: 1486 | IH5: 1959 | II5: 166364 | IJ5: 113304 | IK5: 16421 | IL5: 410 | IM5: 302 | IN5: 164 | IO5: 18 | IP5: 443 | IQ5: 1421 | IR5: 2182 | IS5: 4095 | IT5: 8429 | IU5: 10779 | IV5: 3616 | IW5: 1620 | IX5: 2892 | IY5: 9100 | IZ5: 16760 | JA5: 28690 | JB5: 30508 | JC5: 15211
A6: 1994 | B6: 2973316 | C6: 497903 | D6: 1497402 | E6: 1475914 | F6: 0 | G6: 24919 | H6: 25271 | I6: 25668 | J6: 48983 | K6: 24055 | L6: 23926 | M6: 23629 | N6: 23311 | O6: 22855 | P6: 22528 | Q6: 22251 | R6: 22064 | S6: 21845 | T6: 21626 | U6: 21545 | V6: 21636 | W6: 21859 | X6: 22278 | Y6: 22888 | Z6: 23370 | AA6: 23718 | AB6: 24011 | AC6: 24367 | AD6: 24641 | AE6: 25081 | AF6: 25557 | AG6: 26265 | AH6: 27369 | AI6: 28465 | AJ6: 29467 | AK6: 30226 | AL6: 30663 | AM6: 30918 | AN6: 31139 | AO6: 31219 | AP6: 30886 | AQ6: 30152 | AR6: 29144 | AS6: 28094 | AT6: 27174 | AU6: 26321 | AV6: 25408 | AW6: 24361 | AX6: 23130 | AY6: 22039 | AZ6: 20796 | BA6: 19467 | BB6: 17881 | BC6: 16094 | BD6: 14608 | BE6: 13504 | BF6: 12921 | BG6: 12520 | BH6: 12198 | BI6: 11986 | BJ6: 11677 | BK6: 11328 | BL6: 10868 | BM6: 10390 | BN6: 10020 | BO6: 9635 | BP6: 9274 | BQ6: 8791 | BR6: 8313 | BS6: 8012 | BT6: 7572 | BU6: 7105 | BV6: 6546 | BW6: 6046 | BX6: 5645 | BY6: 5251 | BZ6: 4785 | CA6: 4393 | CB6: 3987 | CC6: 3709 | CD6: 3340 | CE6: 3057 | CF6: 2728 | CG6: 2469 | CH6: 2237 | CI6: 2008 | CJ6: 1773 | CK6: 1525 | CL6: 1255 | CM6: 1092 | CN6: 884 | CO6: 760 | CP6: 631 | CQ6: 517 | CR6: 413 | CS6: 389 | CT6: 349 | CU6: 331 | CV6: 0 | CW6: 0 | CX6: 0 | CY6: 0 | CZ6: 0 | DA6: 0 | DB6: 31.212742 | DC6: 0 | DD6: 27193 | DE6: 27335 | DF6: 27867 | DG6: 49361 | DH6: 22342 | DI6: 22254 | DJ6: 22045 | DK6: 21656 | DL6: 21223 | DM6: 20842 | DN6: 20555 | DO6: 20350 | DP6: 20191 | DQ6: 20047 | DR6: 19978 | DS6: 19989 | DT6: 20272 | DU6: 20794 | DV6: 21367 | DW6: 21900 | DX6: 22328 | DY6: 22714 | DZ6: 23111 | EA6: 23540 | EB6: 24002 | EC6: 24489 | ED6: 25297 | EE6: 26286 | EF6: 27574 | EG6: 28592 | EH6: 29242 | EI6: 29680 | EJ6: 29818 | EK6: 29996 | EL6: 30056 | EM6: 29761 | EN6: 29175 | EO6: 28278 | EP6: 27186 | EQ6: 26260 | ER6: 25572 | ES6: 24761 | ET6: 23727 | EU6: 22508 | EV6: 21514 | EW6: 20470 | EX6: 19317 | EY6: 17779 | EZ6: 15914 | FA6: 14394 | FB6: 13307 | FC6: 12828 | FD6: 12565 | FE6: 12235 | FF6: 12042 | FG6: 11811 | FH6: 11493 | FI6: 11071 | FJ6: 10707 | FK6: 10345 | FL6: 10039 | FM6: 9675 | FN6: 9300 | FO6: 8886 | FP6: 8518 | FQ6: 8119 | FR6: 7695 | FS6: 7174 | FT6: 6636 | FU6: 6171 | FV6: 5810 | FW6: 5454 | FX6: 5210 | FY6: 4819 | FZ6: 4612 | GA6: 4311 | GB6: 4063 | GC6: 3749 | GD6: 3467 | GE6: 3187 | GF6: 2958 | GG6: 2719 | GH6: 2359 | GI6: 2003 | GJ6: 1708 | GK6: 1530 | GL6: 1295 | GM6: 1086 | GN6: 950 | GO6: 835 | GP6: 745 | GQ6: 768 | GR6: 756 | GS6: 0 | GT6: 0 | GU6: 0 | GV6: 0 | GW6: 0 | GX6: 0 | GY6: 32.083298 | GZ6: 3055 | HA6: 7142 | HB6: 6734 | HC6: 3048 | HD6: 1471 | HE6: 563 | HF6: 128 | HG6: 3588 | HH6: 10660 | HI6: 10371 | HJ6: 4778 | HK6: 1992 | HL6: 612 | HM6: 162 | HN6: 80232 | HO6: 198655 | HP6: 180799 | HQ6: 109748 | HR6: 63595 | HS6: 25783 | HT6: 8191 | HU6: 91661 | HV6: 146643 | HW6: 176076 | HX6: 100536 | HY6: 55485 | HZ6: 16048 | IA6: 6190 | IB6: 169191 | IC6: 94830 | ID6: 32888 | IE6: 5033 | IF6: 7613 | IG6: 1123 | IH6: 2070 | II6: 144187 | IJ6: 131734 | IK6: 21743 | IL6: 801 | IM6: 580 | IN6: 301 | IO6: 41 | IP6: 366 | IQ6: 1281 | IR6: 2250 | IS6: 4171 | IT6: 8635 | IU6: 11895 | IV6: 3775 | IW6: 1805 | IX6: 2747 | IY6: 9632 | IZ6: 16338 | JA6: 28330 | JB6: 30705 | JC6: 16507
A7: 1995 | B7: 3036851 | C7: 549981 | D7: 1527705 | E7: 1509146 | F7: 0 | G7: 25174 | H7: 24975 | I7: 25393 | J7: 26073 | K7: 49262 | L7: 24370 | M7: 24204 | N7: 23890 | O7: 23604 | P7: 23164 | Q7: 22848 | R7: 22532 | S7: 22312 | T7: 22136 | U7: 21904 | V7: 21813 | W7: 21902 | X7: 22156 | Y7: 22535 | Z7: 23177 | AA7: 23635 | AB7: 23986 | AC7: 24277 | AD7: 24678 | AE7: 24979 | AF7: 25420 | AG7: 25890 | AH7: 26572 | AI7: 27700 | AJ7: 28784 | AK7: 29836 | AL7: 30556 | AM7: 31050 | AN7: 31303 | AO7: 31529 | AP7: 31417 | AQ7: 31028 | AR7: 30252 | AS7: 29191 | AT7: 28167 | AU7: 27203 | AV7: 26337 | AW7: 25448 | AX7: 24400 | AY7: 23156 | AZ7: 22031 | BA7: 20777 | BB7: 19477 | BC7: 17879 | BD7: 16095 | BE7: 14565 | BF7: 13467 | BG7: 12893 | BH7: 12485 | BI7: 12173 | BJ7: 11881 | BK7: 11604 | BL7: 11248 | BM7: 10786 | BN7: 10322 | BO7: 9890 | BP7: 9485 | BQ7: 9136 | BR7: 8667 | BS7: 8206 | BT7: 7792 | BU7: 7400 | BV7: 6938 | BW7: 6366 | BX7: 5870 | BY7: 5424 | BZ7: 5061 | CA7: 4593 | CB7: 4250 | CC7: 3828 | CD7: 3470 | CE7: 3136 | CF7: 2872 | CG7: 2553 | CH7: 2309 | CI7: 2046 | CJ7: 1794 | CK7: 1591 | CL7: 1354 | CM7: 1122 | CN7: 938 | CO7: 755 | CP7: 662 | CQ7: 560 | CR7: 451 | CS7: 349 | CT7: 336 | CU7: 307 | CV7: 293 | CW7: 0 | CX7: 0 | CY7: 0 | CZ7: 0 | DA7: 0 | DB7: 31.467139 | DC7: 0 | DD7: 27154 | DE7: 27232 | DF7: 27453 | DG7: 28146 | DH7: 49601 | DI7: 22578 | DJ7: 22463 | DK7: 22258 | DL7: 21853 | DM7: 21423 | DN7: 21064 | DO7: 20770 | DP7: 20555 | DQ7: 20391 | DR7: 20259 | DS7: 20176 | DT7: 20205 | DU7: 20502 | DV7: 20983 | DW7: 21598 | DX7: 22140 | DY7: 22545 | DZ7: 22933 | EA7: 23359 | EB7: 23773 | EC7: 24281 | ED7: 24716 | EE7: 25574 | EF7: 26555 | EG7: 27839 | EH7: 28883 | EI7: 29507 | EJ7: 29968 | EK7: 30104 | EL7: 30294 | EM7: 30220 | EN7: 29906 | EO7: 29344 | EP7: 28430 | EQ7: 27323 | ER7: 26389 | ES7: 25746 | ET7: 24885 | EU7: 23830 | EV7: 22598 | EW7: 21627 | EX7: 20574 | EY7: 19412 | EZ7: 17851 | FA7: 15983 | FB7: 14442 | FC7: 13354 | FD7: 12874 | FE7: 12618 | FF7: 12272 | FG7: 12053 | FH7: 11818 | FI7: 11509 | FJ7: 11095 | FK7: 10703 | FL7: 10327 | FM7: 10034 | FN7: 9675 | FO7: 9298 | FP7: 8869 | FQ7: 8436 | FR7: 8055 | FS7: 7627 | FT7: 7090 | FU7: 6562 | FV7: 6045 | FW7: 5682 | FX7: 5351 | FY7: 5118 | FZ7: 4712 | GA7: 4432 | GB7: 4118 | GC7: 3901 | GD7: 3616 | GE7: 3324 | GF7: 2954 | GG7: 2776 | GH7: 2550 | GI7: 2216 | GJ7: 1872 | GK7: 1500 | GL7: 1338 | GM7: 1142 | GN7: 963 | GO7: 826 | GP7: 736 | GQ7: 650 | GR7: 691 | GS7: 668 | GT7: 0 | GU7: 0 | GV7: 0 | GW7: 0 | GX7: 0 | GY7: 32.333903 | GZ7: 3223 | HA7: 7929 | HB7: 7729 | HC7: 3540 | HD7: 1705 | HE7: 663 | HF7: 161 | HG7: 3531 | HH7: 11246 | HI7: 11816 | HJ7: 5482 | HK7: 2330 | HL7: 701 | HM7: 196 | HN7: 76830 | HO7: 201213 | HP7: 188974 | HQ7: 114137 | HR7: 65910 | HS7: 26282 | HT7: 8671 | HU7: 116983 | HV7: 132080 | HW7: 179558 | HX7: 105258 | HY7: 58808 | HZ7: 17445 | IA7: 6171 | IB7: 169978 | IC7: 94653 | ID7: 35858 | IE7: 5323 | IF7: 7907 | IG7: 1048 | IH7: 2123 | II7: 114973 | IJ7: 148586 | IK7: 28735 | IL7: 1277 | IM7: 921 | IN7: 489 | IO7: 74 | IP7: 283 | IQ7: 1151 | IR7: 2314 | IS7: 4197 | IT7: 8680 | IU7: 13064 | IV7: 3912 | IW7: 1987 | IX7: 2583 | IY7: 10126 | IZ7: 16001 | JA7: 28055 | JB7: 30902 | JC7: 17766
A8: 1996 | B8: 3100020 | C8: 593639 | D8: 1557819 | E8: 1542201 | F8: 0 | G8: 24576 | H8: 25217 | I8: 25100 | J8: 25552 | K8: 26523 | L8: 49569 | M8: 24681 | N8: 24535 | O8: 24177 | P8: 23904 | Q8: 23453 | R8: 23153 | S8: 22811 | T8: 22600 | U8: 22422 | V8: 22181 | W8: 22097 | X8: 22195 | Y8: 22451 | Z8: 22823 | AA8: 23498 | AB8: 23933 | AC8: 24261 | AD8: 24603 | AE8: 25002 | AF8: 25310 | AG8: 25726 | AH8: 26248 | AI8: 26911 | AJ8: 28022 | AK8: 29152 | AL8: 30200 | AM8: 30965 | AN8: 31448 | AO8: 31674 | AP8: 31732 | AQ8: 31586 | AR8: 31161 | AS8: 30334 | AT8: 29256 | AU8: 28194 | AV8: 27221 | AW8: 26362 | AX8: 25471 | AY8: 24439 | AZ8: 23151 | BA8: 22020 | BB8: 20775 | BC8: 19488 | BD8: 17878 | BE8: 16064 | BF8: 14521 | BG8: 13440 | BH8: 12857 | BI8: 12462 | BJ8: 12094 | BK8: 11805 | BL8: 11539 | BM8: 11206 | BN8: 10723 | BO8: 10187 | BP8: 9744 | BQ8: 9331 | BR8: 9033 | BS8: 8530 | BT8: 8033 | BU8: 7604 | BV8: 7235 | BW8: 6747 | BX8: 6216 | BY8: 5643 | BZ8: 5221 | CA8: 4860 | CB8: 4403 | CC8: 4084 | CD8: 3568 | CE8: 3277 | CF8: 2938 | CG8: 2723 | CH8: 2409 | CI8: 2089 | CJ8: 1866 | CK8: 1627 | CL8: 1474 | CM8: 1235 | CN8: 946 | CO8: 813 | CP8: 668 | CQ8: 574 | CR8: 479 | CS8: 402 | CT8: 313 | CU8: 290 | CV8: 263 | CW8: 242 | CX8: 0 | CY8: 0 | CZ8: 0 | DA8: 0 | DB8: 31.742883 | DC8: 0 | DD8: 26955 | DE8: 27184 | DF8: 27334 | DG8: 27553 | DH8: 28451 | DI8: 49818 | DJ8: 22796 | DK8: 22685 | DL8: 22495 | DM8: 22079 | DN8: 21650 | DO8: 21247 | DP8: 21017 | DQ8: 20727 | DR8: 20605 | DS8: 20431 | DT8: 20373 | DU8: 20408 | DV8: 20727 | DW8: 21186 | DX8: 21823 | DY8: 22379 | DZ8: 22785 | EA8: 23171 | EB8: 23595 | EC8: 24013 | ED8: 24535 | EE8: 24968 | EF8: 25845 | EG8: 26844 | EH8: 28146 | EI8: 29157 | EJ8: 29833 | EK8: 30267 | EL8: 30401 | EM8: 30454 | EN8: 30382 | EO8: 30077 | EP8: 29493 | EQ8: 28582 | ER8: 27454 | ES8: 26486 | ET8: 25869 | EU8: 24996 | EV8: 23928 | EW8: 22710 | EX8: 21729 | EY8: 20675 | EZ8: 19526 | FA8: 17955 | FB8: 16033 | FC8: 14473 | FD8: 13401 | FE8: 12916 | FF8: 12668 | FG8: 12261 | FH8: 12066 | FI8: 11849 | FJ8: 11535 | FK8: 11088 | FL8: 10704 | FM8: 10321 | FN8: 10020 | FO8: 9679 | FP8: 9277 | FQ8: 8797 | FR8: 8355 | FS8: 7963 | FT8: 7552 | FU8: 7038 | FV8: 6449 | FW8: 5923 | FX8: 5572 | FY8: 5237 | FZ8: 4997 | GA8: 4538 | GB8: 4297 | GC8: 3990 | GD8: 3737 | GE8: 3495 | GF8: 3132 | GG8: 2785 | GH8: 2593 | GI8: 2393 | GJ8: 2069 | GK8: 1652 | GL8: 1324 | GM8: 1187 | GN8: 1013 | GO8: 869 | GP8: 745 | GQ8: 642 | GR8: 560 | GS8: 610 | GT8: 596 | GU8: 0 | GV8: 0 | GW8: 0 | GX8: 0 | GY8: 32.603219 | GZ8: 3297 | HA8: 8575 | HB8: 8941 | HC8: 3998 | HD8: 1965 | HE8: 733 | HF8: 207 | HG8: 3501 | HH8: 11469 | HI8: 13501 | HJ8: 6242 | HK8: 2653 | HL8: 822 | HM8: 218 | HN8: 73305 | HO8: 203459 | HP8: 197227 | HQ8: 119050 | HR8: 68402 | HS8: 26769 | HT8: 9261 | HU8: 143459 | HV8: 116691 | HW8: 181466 | HX8: 110762 | HY8: 62072 | HZ8: 19021 | IA8: 6259 | IB8: 171477 | IC8: 93210 | ID8: 37875 | IE8: 6596 | IF8: 8065 | IG8: 1356 | IH8: 2126 | II8: 85107 | IJ8: 164512 | IK8: 37193 | IL8: 1847 | IM8: 1337 | IN8: 698 | IO8: 139 | IP8: 236 | IQ8: 1030 | IR8: 2334 | IS8: 4222 | IT8: 8735 | IU8: 14075 | IV8: 4096 | IW8: 2233 | IX8: 2382 | IY8: 9795 | IZ8: 16306 | JA8: 27694 | JB8: 31237 | JC8: 19050
A9: 1997 | B9: 3161849 | C9: 628201 | D9: 1587484 | E9: 1574365 | F9: 0 | G9: 24321 | H9: 24621 | I9: 25309 | J9: 25246 | K9: 25718 | L9: 27030 | M9: 49883 | N9: 24993 | O9: 24883 | P9: 24485 | Q9: 24219 | R9: 23762 | S9: 23462 | T9: 23113 | U9: 22880 | V9: 22732 | W9: 22452 | X9: 22392 | Y9: 22516 | Z9: 22745 | AA9: 23101 | AB9: 23803 | AC9: 24217 | AD9: 24555 | AE9: 24922 | AF9: 25337 | AG9: 25658 | AH9: 26024 | AI9: 26585 | AJ9: 27213 | AK9: 28422 | AL9: 29520 | AM9: 30644 | AN9: 31354 | AO9: 31820 | AP9: 31902 | AQ9: 31942 | AR9: 31728 | AS9: 31258 | AT9: 30409 | AU9: 29291 | AV9: 28203 | AW9: 27232 | AX9: 26379 | AY9: 25499 | AZ9: 24422 | BA9: 23141 | BB9: 21993 | BC9: 20756 | BD9: 19493 | BE9: 17821 | BF9: 16018 | BG9: 14469 | BH9: 13412 | BI9: 12830 | BJ9: 12373 | BK9: 11986 | BL9: 11737 | BM9: 11440 | BN9: 11138 | BO9: 10574 | BP9: 10064 | BQ9: 9605 | BR9: 9222 | BS9: 8914 | BT9: 8354 | BU9: 7845 | BV9: 7438 | BW9: 7079 | BX9: 6591 | BY9: 5973 | BZ9: 5406 | CA9: 5002 | CB9: 4682 | CC9: 4252 | CD9: 3830 | CE9: 3364 | CF9: 3080 | CG9: 2784 | CH9: 2563 | CI9: 2210 | CJ9: 1897 | CK9: 1697 | CL9: 1466 | CM9: 1354 | CN9: 1068 | CO9: 810 | CP9: 715 | CQ9: 582 | CR9: 507 | CS9: 419 | CT9: 353 | CU9: 280 | CV9: 248 | CW9: 234 | CX9: 213 | CY9: 0 | CZ9: 0 | DA9: 0 | DB9: 32.027717 | DC9: 0 | DD9: 26500 | DE9: 26980 | DF9: 27236 | DG9: 27439 | DH9: 27670 | DI9: 28774 | DJ9: 50038 | DK9: 23024 | DL9: 22918 | DM9: 22700 | DN9: 22286 | DO9: 21878 | DP9: 21462 | DQ9: 21233 | DR9: 20934 | DS9: 20802 | DT9: 20622 | DU9: 20581 | DV9: 20601 | DW9: 20919 | DX9: 21400 | DY9: 22039 | DZ9: 22572 | EA9: 22993 | EB9: 23394 | EC9: 23815 | ED9: 24246 | EE9: 24802 | EF9: 25251 | EG9: 26103 | EH9: 27141 | EI9: 28458 | EJ9: 29430 | EK9: 30124 | EL9: 30572 | EM9: 30528 | EN9: 30617 | EO9: 30532 | EP9: 30225 | EQ9: 29668 | ER9: 28727 | ES9: 27596 | ET9: 26602 | EU9: 26003 | EV9: 25116 | EW9: 24039 | EX9: 22814 | EY9: 21800 | EZ9: 20742 | FA9: 19586 | FB9: 18022 | FC9: 16095 | FD9: 14520 | FE9: 13444 | FF9: 12967 | FG9: 12672 | FH9: 12273 | FI9: 12075 | FJ9: 11864 | FK9: 11551 | FL9: 11078 | FM9: 10688 | FN9: 10299 | FO9: 10003 | FP9: 9628 | FQ9: 9189 | FR9: 8728 | FS9: 8300 | FT9: 7891 | FU9: 7494 | FV9: 6902 | FW9: 6300 | FX9: 5809 | FY9: 5470 | FZ9: 5137 | GA9: 4832 | GB9: 4399 | GC9: 4165 | GD9: 3862 | GE9: 3626 | GF9: 3299 | GG9: 2974 | GH9: 2594 | GI9: 2455 | GJ9: 2258 | GK9: 1802 | GL9: 1469 | GM9: 1161 | GN9: 1047 | GO9: 921 | GP9: 769 | GQ9: 659 | GR9: 563 | GS9: 492 | GT9: 553 | GU9: 533 | GV9: 0 | GW9: 0 | GX9: 0 | GY9: 32.891863 | GZ9: 3268 | HA9: 9143 | HB9: 10105 | HC9: 4531 | HD9: 2215 | HE9: 829 | HF9: 253 | HG9: 3357 | HH9: 11353 | HI9: 15208 | HJ9: 7079 | HK9: 2992 | HL9: 970 | HM9: 263 | HN9: 69998 | HO9: 203961 | HP9: 205928 | HQ9: 124259 | HR9: 71168 | HS9: 27213 | HT9: 9962 | HU9: 170246 | HV9: 100459 | HW9: 182748 | HX9: 116345 | HY9: 65165 | HZ9: 20883 | IA9: 6355 | IB9: 173496 | IC9: 91804 | ID9: 38882 | IE9: 8606 | IF9: 8103 | IG9: 1927 | IH9: 2113 | II9: 55334 | IJ9: 179764 | IK9: 46670 | IL9: 2506 | IM9: 1767 | IN9: 941 | IO9: 229 | IP9: 185 | IQ9: 895 | IR9: 2410 | IS9: 4183 | IT9: 8747 | IU9: 14995 | IV9: 4288 | IW9: 2494 | IX9: 2154 | IY9: 8481 | IZ9: 17588 | JA9: 27431 | JB9: 31576 | JC9: 20329
A10: 1998 | B10: 3221116 | C10: 654152 | D10: 1615869 | E10: 1605247 | F10: 0 | G10: 23745 | H10: 24360 | I10: 24694 | J10: 25421 | K10: 25389 | L10: 25911 | M10: 27545 | N10: 50198 | O10: 25303 | P10: 25187 | Q10: 24771 | R10: 24502 | S10: 24066 | T10: 23760 | U10: 23415 | V10: 23157 | W10: 23005 | X10: 22730 | Y10: 22660 | Z10: 22786 | AA10: 23019 | AB10: 23379 | AC10: 24121 | AD10: 24502 | AE10: 24851 | AF10: 25245 | AG10: 25676 | AH10: 25953 | AI10: 26353 | AJ10: 26907 | AK10: 27552 | AL10: 28781 | AM10: 29891 | AN10: 31021 | AO10: 31783 | AP10: 32048 | AQ10: 32110 | AR10: 32132 | AS10: 31855 | AT10: 31354 | AU10: 30454 | AV10: 29319 | AW10: 28209 | AX10: 27248 | AY10: 26395 | AZ10: 25487 | BA10: 24380 | BB10: 23126 | BC10: 21977 | BD10: 20739 | BE10: 19430 | BF10: 17758 | BG10: 15984 | BH10: 14429 | BI10: 13374 | BJ10: 12746 | BK10: 12293 | BL10: 11918 | BM10: 11683 | BN10: 11374 | BO10: 10978 | BP10: 10426 | BQ10: 9919 | BR10: 9496 | BS10: 9074 | BT10: 8738 | BU10: 8186 | BV10: 7679 | BW10: 7287 | BX10: 6923 | BY10: 6338 | BZ10: 5738 | CA10: 5211 | CB10: 4817 | CC10: 4531 | CD10: 3993 | CE10: 3615 | CF10: 3177 | CG10: 2890 | CH10: 2621 | CI10: 2338 | CJ10: 2013 | CK10: 1714 | CL10: 1532 | CM10: 1335 | CN10: 1169 | CO10: 910 | CP10: 712 | CQ10: 608 | CR10: 484 | CS10: 442 | CT10: 368 | CU10: 306 | CV10: 240 | CW10: 212 | CX10: 205 | CY10: 183 | CZ10: 0 | DA10: 0 | DB10: 32.329476 | DC10: 0 | DD10: 25836 | DE10: 26524 | DF10: 27027 | DG10: 27296 | DH10: 27543 | DI10: 27828 | DJ10: 29118 | DK10: 50242 | DL10: 23227 | DM10: 23126 | DN10: 22911 | DO10: 22501 | DP10: 22093 | DQ10: 21658 | DR10: 21444 | DS10: 21139 | DT10: 20988 | DU10: 20842 | DV10: 20793 | DW10: 20785 | DX10: 21139 | DY10: 21599 | DZ10: 22249 | EA10: 22825 | EB10: 23214 | EC10: 23619 | ED10: 24063 | EE10: 24487 | EF10: 25022 | EG10: 25471 | EH10: 26318 | EI10: 27409 | EJ10: 28770 | EK10: 29653 | EL10: 30398 | EM10: 30706 | EN10: 30685 | EO10: 30754 | EP10: 30695 | EQ10: 30389 | ER10: 29801 | ES10: 28861 | ET10: 27753 | EU10: 26744 | EV10: 26130 | EW10: 25216 | EX10: 24121 | EY10: 22905 | EZ10: 21907 | FA10: 20839 | FB10: 19641 | FC10: 18075 | FD10: 16152 | FE10: 14575 | FF10: 13498 | FG10: 13000 | FH10: 12686 | FI10: 12272 | FJ10: 12080 | FK10: 11874 | FL10: 11525 | FM10: 11062 | FN10: 10670 | FO10: 10281 | FP10: 9983 | FQ10: 9534 | FR10: 9121 | FS10: 8675 | FT10: 8238 | FU10: 7809 | FV10: 7393 | FW10: 6805 | FX10: 6194 | FY10: 5696 | FZ10: 5361 | GA10: 4976 | GB10: 4663 | GC10: 4284 | GD10: 4017 | GE10: 3721 | GF10: 3400 | GG10: 3104 | GH10: 2797 | GI10: 2428 | GJ10: 2298 | GK10: 1972 | GL10: 1577 | GM10: 1282 | GN10: 1026 | GO10: 919 | GP10: 818 | GQ10: 669 | GR10: 581 | GS10: 497 | GT10: 422 | GU10: 480 | GV10: 452 | GW10: 0 | GX10: 0 | GY10: 33.194446 | GZ10: 3298 | HA10: 9600 | HB10: 11426 | HC10: 5148 | HD10: 2476 | HE10: 944 | HF10: 285 | HG10: 2945 | HH10: 11135 | HI10: 17071 | HJ10: 8018 | HK10: 3393 | HL10: 1106 | HM10: 304 | HN10: 67151 | HO10: 203431 | HP10: 214401 | HQ10: 130017 | HR10: 74053 | HS10: 27750 | HT10: 10573 | HU10: 191568 | HV10: 89685 | HW10: 183636 | HX10: 121421 | HY10: 68128 | HZ10: 22913 | IA10: 6378 | IB10: 175291 | IC10: 90310 | ID10: 39678 | IE10: 11009 | IF10: 7971 | IG10: 2636 | IH10: 2036 | II10: 32063 | IJ10: 187763 | IK10: 57026 | IL10: 3554 | IM10: 2224 | IN10: 1215 | IO10: 312 | IP10: 145 | IQ10: 739 | IR10: 2444 | IS10: 4180 | IT10: 8657 | IU10: 15903 | IV10: 4498 | IW10: 2426 | IX10: 2276 | IY10: 6094 | IZ10: 19825 | JA10: 27218 | JB10: 31964 | JC10: 21450
A11: 1999 | B11: 3278084 | C11: 673177 | D11: 1643482 | E11: 1634602 | F11: 0 | G11: 23594 | H11: 23777 | I11: 24417 | J11: 24791 | K11: 25555 | L11: 25541 | M11: 26143 | N11: 28083 | O11: 50504 | P11: 25604 | Q11: 25485 | R11: 25051 | S11: 24792 | T11: 24327 | U11: 24010 | V11: 23702 | W11: 23429 | X11: 23272 | Y11: 22984 | Z11: 22941 | AA11: 23040 | AB11: 23291 | AC11: 23698 | AD11: 24416 | AE11: 24765 | AF11: 25160 | AG11: 25556 | AH11: 25972 | AI11: 26259 | AJ11: 26663 | AK11: 27210 | AL11: 27855 | AM11: 29131 | AN11: 30224 | AO11: 31385 | AP11: 32036 | AQ11: 32263 | AR11: 32295 | AS11: 32300 | AT11: 31993 | AU11: 31438 | AV11: 30477 | AW11: 29330 | AX11: 28220 | AY11: 27266 | AZ11: 26366 | BA11: 25452 | BB11: 24374 | BC11: 23103 | BD11: 21966 | BE11: 20678 | BF11: 19351 | BG11: 17696 | BH11: 15945 | BI11: 14396 | BJ11: 13274 | BK11: 12667 | BL11: 12210 | BM11: 11851 | BN11: 11604 | BO11: 11231 | BP11: 10827 | BQ11: 10277 | BR11: 9784 | BS11: 9353 | BT11: 8876 | BU11: 8565 | BV11: 8022 | BW11: 7513 | BX11: 7124 | BY11: 6691 | BZ11: 6118 | CA11: 5536 | CB11: 4997 | CC11: 4666 | CD11: 4277 | CE11: 3782 | CF11: 3418 | CG11: 3002 | CH11: 2747 | CI11: 2399 | CJ11: 2151 | CK11: 1838 | CL11: 1549 | CM11: 1392 | CN11: 1138 | CO11: 1029 | CP11: 783 | CQ11: 608 | CR11: 518 | CS11: 410 | CT11: 374 | CU11: 319 | CV11: 261 | CW11: 206 | CX11: 186 | CY11: 173 | CZ11: 164 | DA11: 0 | DB11: 32.642218 | DC11: 0 | DD11: 25246 | DE11: 25844 | DF11: 26555 | DG11: 27079 | DH11: 27387 | DI11: 27648 | DJ11: 27975 | DK11: 29425 | DL11: 50450 | DM11: 23455 | DN11: 23327 | DO11: 23114 | DP11: 22693 | DQ11: 22305 | DR11: 21832 | DS11: 21634 | DT11: 21342 | DU11: 21159 | DV11: 21015 | DW11: 20981 | DX11: 20970 | DY11: 21318 | DZ11: 21794 | EA11: 22446 | EB11: 23021 | EC11: 23415 | ED11: 23834 | EE11: 24288 | EF11: 24692 | EG11: 25227 | EH11: 25689 | EI11: 26550 | EJ11: 27697 | EK11: 29036 | EL11: 29959 | EM11: 30524 | EN11: 30846 | EO11: 30827 | EP11: 30892 | EQ11: 30841 | ER11: 30529 | ES11: 29938 | ET11: 28981 | EU11: 27870 | EV11: 26862 | EW11: 26235 | EX11: 25299 | EY11: 24174 | EZ11: 23004 | FA11: 21991 | FB11: 20892 | FC11: 19699 | FD11: 18107 | FE11: 16178 | FF11: 14620 | FG11: 13501 | FH11: 13021 | FI11: 12694 | FJ11: 12287 | FK11: 12106 | FL11: 11845 | FM11: 11510 | FN11: 11044 | FO11: 10645 | FP11: 10260 | FQ11: 9909 | FR11: 9466 | FS11: 9056 | FT11: 8598 | FU11: 8168 | FV11: 7651 | FW11: 7274 | FX11: 6683 | FY11: 6080 | FZ11: 5579 | GA11: 5201 | GB11: 4811 | GC11: 4489 | GD11: 4147 | GE11: 3875 | GF11: 3519 | GG11: 3199 | GH11: 2939 | GI11: 2638 | GJ11: 2293 | GK11: 2007 | GL11: 1737 | GM11: 1374 | GN11: 1134 | GO11: 875 | GP11: 814 | GQ11: 727 | GR11: 587 | GS11: 520 | GT11: 428 | GU11: 372 | GV11: 428 | GW11: 399 | GX11: 0 | GY11: 33.516755 | GZ11: 3249 | HA11: 9970 | HB11: 12632 | HC11: 5896 | HD11: 2729 | HE11: 1083 | HF11: 344 | HG11: 1511 | HH11: 11616 | HI11: 18883 | HJ11: 9143 | HK11: 3787 | HL11: 1274 | HM11: 360 | HN11: 64452 | HO11: 201811 | HP11: 222897 | HQ11: 136059 | HR11: 77010 | HS11: 29426 | HT11: 10215 | HU11: 200511 | HV11: 92125 | HW11: 184239 | HX11: 125379 | HY11: 70830 | HZ11: 25095 | IA11: 6402 | IB11: 177270 | IC11: 88916 | ID11: 40088 | IE11: 13868 | IF11: 7634 | IG11: 3427 | IH11: 1826 | II11: 23371 | IJ11: 180157 | IK11: 64658 | IL11: 8686 | IM11: 2694 | IN11: 1544 | IO11: 432 | IP11: 127 | IQ11: 665 | IR11: 2402 | IS11: 4211 | IT11: 8679 | IU11: 15675 | IV11: 5860 | IW11: 1366 | IX11: 3349 | IY11: 5953 | IZ11: 19782 | JA11: 27128 | JB11: 32170 | JC11: 22672
A12: 2000 | B12: 3331728 | C12: 688062 | D12: 1669444 | E12: 1662284 | F12: 0 | G12: 22562 | H12: 23613 | I12: 23807 | J12: 24494 | K12: 24898 | L12: 25677 | M12: 25724 | N12: 26356 | O12: 28571 | P12: 50809 | Q12: 25921 | R12: 25777 | S12: 25306 | T12: 25061 | U12: 24607 | V12: 24292 | W12: 23949 | X12: 23724 | Y12: 23528 | Z12: 23245 | AA12: 23181 | AB12: 23287 | AC12: 23602 | AD12: 23945 | AE12: 24682 | AF12: 25058 | AG12: 25462 | AH12: 25847 | AI12: 26273 | AJ12: 26591 | AK12: 26974 | AL12: 27524 | AM12: 28178 | AN12: 29479 | AO12: 30539 | AP12: 31644 | AQ12: 32256 | AR12: 32477 | AS12: 32448 | AT12: 32449 | AU12: 32069 | AV12: 31483 | AW12: 30499 | AX12: 29327 | AY12: 28225 | AZ12: 27227 | BA12: 26326 | BB12: 25422 | BC12: 24343 | BD12: 23076 | BE12: 21896 | BF12: 20627 | BG12: 19302 | BH12: 17643 | BI12: 15874 | BJ12: 14296 | BK12: 13205 | BL12: 12590 | BM12: 12135 | BN12: 11772 | BO12: 11441 | BP12: 11109 | BQ12: 10674 | BR12: 10141 | BS12: 9664 | BT12: 9154 | BU12: 8679 | BV12: 8366 | BW12: 7834 | BX12: 7352 | BY12: 6909 | BZ12: 6505 | CA12: 5937 | CB12: 5354 | CC12: 4831 | CD12: 4405 | CE12: 4025 | CF12: 3578 | CG12: 3235 | CH12: 2842 | CI12: 2501 | CJ12: 2209 | CK12: 1958 | CL12: 1672 | CM12: 1416 | CN12: 1196 | CO12: 975 | CP12: 876 | CQ12: 666 | CR12: 529 | CS12: 446 | CT12: 366 | CU12: 321 | CV12: 279 | CW12: 218 | CX12: 177 | CY12: 159 | CZ12: 147 | DA12: 144 | DB12: 32.981187 | DC12: 0 | DD12: 24376 | DE12: 25256 | DF12: 25868 | DG12: 26613 | DH12: 27144 | DI12: 27479 | DJ12: 27769 | DK12: 28100 | DL12: 29756 | DM12: 50640 | DN12: 23644 | DO12: 23513 | DP12: 23319 | DQ12: 22887 | DR12: 22512 | DS12: 22037 | DT12: 21801 | DU12: 21518 | DV12: 21318 | DW12: 21182 | DX12: 21175 | DY12: 21142 | DZ12: 21482 | EA12: 21983 | EB12: 22625 | EC12: 23217 | ED12: 23589 | EE12: 24024 | EF12: 24487 | EG12: 24879 | EH12: 25449 | EI12: 25895 | EJ12: 26787 | EK12: 27941 | EL12: 29284 | EM12: 30082 | EN12: 30643 | EO12: 30968 | EP12: 30965 | EQ12: 31023 | ER12: 30941 | ES12: 30634 | ET12: 30070 | EU12: 29113 | EV12: 28008 | EW12: 26956 | EX12: 26302 | EY12: 25383 | EZ12: 24261 | FA12: 23088 | FB12: 22020 | FC12: 20938 | FD12: 19734 | FE12: 18139 | FF12: 16219 | FG12: 14626 | FH12: 13509 | FI12: 13028 | FJ12: 12698 | FK12: 12289 | FL12: 12084 | FM12: 11816 | FN12: 11467 | FO12: 11016 | FP12: 10616 | FQ12: 10164 | FR12: 9832 | FS12: 9397 | FT12: 8974 | FU12: 8532 | FV12: 8023 | FW12: 7537 | FX12: 7157 | FY12: 6581 | FZ12: 5983 | GA12: 5412 | GB12: 5044 | GC12: 4655 | GD12: 4341 | GE12: 3989 | GF12: 3633 | GG12: 3344 | GH12: 3029 | GI12: 2781 | GJ12: 2490 | GK12: 2041 | GL12: 1755 | GM12: 1504 | GN12: 1200 | GO12: 1003 | GP12: 760 | GQ12: 703 | GR12: 655 | GS12: 523 | GT12: 458 | GU12: 381 | GV12: 331 | GW12: 379 | GX12: 365 | GY12: 33.862126 | GZ12: 2067 | HA12: 11209 | HB12: 13953 | HC12: 6651 | HD12: 3005 | HE12: 1265 | HF12: 365 | HG12: 0 | HH12: 9241 | HI12: 20679 | HJ12: 10345 | HK12: 4241 | HL12: 1483 | HM12: 419 | HN12: 55782 | HO12: 206352 | HP12: 230398 | HQ12: 142743 | HR12: 80060 | HS12: 31498 | HT12: 9835 | HU12: 204916 | HV12: 100281 | HW12: 182734 | HX12: 129801 | HY12: 73199 | HZ12: 27543 | IA12: 6480 | IB12: 186706 | IC12: 79898 | ID12: 40602 | IE12: 17030 | IF12: 7041 | IG12: 4120 | IH12: 1601 | II12: 19990 | IJ12: 170841 | IK12: 73412 | IL12: 14151 | IM12: 3156 | IN12: 1855 | IO12: 573 | IP12: 27 | IQ12: 651 | IR12: 2417 | IS12: 4220 | IT12: 8728 | IU12: 15248 | IV12: 7296 | IW12: 0 | IX12: 2530 | IY12: 5866 | IZ12: 19702 | JA12: 27059 | JB12: 32384 | JC12: 23853
A13: 2001 | B13: 3383062 | C13: 702437 | D13: 1694024 | E13: 1689038 | F13: 0 | G13: 22075 | H13: 22572 | I13: 23642 | J13: 23866 | K13: 24571 | L13: 25006 | M13: 25811 | N13: 25931 | O13: 26577 | P13: 29066 | Q13: 51096 | R13: 26183 | S13: 26040 | T13: 25564 | U13: 25354 | V13: 24855 | W13: 24543 | X13: 24202 | Y13: 23953 | Z13: 23751 | AA13: 23475 | AB13: 23428 | AC13: 23511 | AD13: 23852 | AE13: 24206 | AF13: 24932 | AG13: 25327 | AH13: 25737 | AI13: 26087 | AJ13: 26565 | AK13: 26879 | AL13: 27267 | AM13: 27793 | AN13: 28509 | AO13: 29796 | AP13: 30737 | AQ13: 31872 | AR13: 32459 | AS13: 32689 | AT13: 32609 | AU13: 32545 | AV13: 32140 | AW13: 31533 | AX13: 30517 | AY13: 29339 | AZ13: 28189 | BA13: 27199 | BB13: 26314 | BC13: 25410 | BD13: 24321 | BE13: 22988 | BF13: 21841 | BG13: 20571 | BH13: 19262 | BI13: 17583 | BJ13: 15767 | BK13: 14207 | BL13: 13114 | BM13: 12509 | BN13: 12053 | BO13: 11608 | BP13: 11324 | BQ13: 10969 | BR13: 10535 | BS13: 10009 | BT13: 9481 | BU13: 8960 | BV13: 8498 | BW13: 8163 | BX13: 7671 | BY13: 7127 | BZ13: 6670 | CA13: 6296 | CB13: 5728 | CC13: 5177 | CD13: 4567 | CE13: 4145 | CF13: 3787 | CG13: 3378 | CH13: 3057 | CI13: 2618 | CJ13: 2302 | CK13: 2001 | CL13: 1791 | CM13: 1524 | CN13: 1221 | CO13: 1047 | CP13: 832 | CQ13: 752 | CR13: 579 | CS13: 473 | CT13: 380 | CU13: 313 | CV13: 270 | CW13: 246 | CX13: 179 | CY13: 155 | CZ13: 140 | DA13: 135 | DB13: 33.33075 | DC13: 0 | DD13: 24148 | DE13: 24382 | DF13: 25270 | DG13: 25900 | DH13: 26665 | DI13: 27213 | DJ13: 27580 | DK13: 27856 | DL13: 28240 | DM13: 30068 | DN13: 50830 | DO13: 23846 | DP13: 23684 | DQ13: 23489 | DR13: 23056 | DS13: 22696 | DT13: 22200 | DU13: 21958 | DV13: 21678 | DW13: 21498 | DX13: 21372 | DY13: 21330 | DZ13: 21299 | EA13: 21658 | EB13: 22162 | EC13: 22802 | ED13: 23385 | EE13: 23775 | EF13: 24203 | EG13: 24673 | EH13: 25078 | EI13: 25655 | EJ13: 26097 | EK13: 26981 | EL13: 28173 | EM13: 29393 | EN13: 30189 | EO13: 30761 | EP13: 31086 | EQ13: 31078 | ER13: 31148 | ES13: 31047 | ET13: 30757 | EU13: 30176 | EV13: 29252 | EW13: 28110 | EX13: 27040 | EY13: 26405 | EZ13: 25455 | FA13: 24333 | FB13: 23113 | FC13: 22074 | FD13: 20979 | FE13: 19776 | FF13: 18158 | FG13: 16219 | FH13: 14631 | FI13: 13511 | FJ13: 13043 | FK13: 12691 | FL13: 12263 | FM13: 12043 | FN13: 11763 | FO13: 11434 | FP13: 10981 | FQ13: 10522 | FR13: 10093 | FS13: 9778 | FT13: 9340 | FU13: 8887 | FV13: 8404 | FW13: 7896 | FX13: 7415 | FY13: 7052 | FZ13: 6478 | GA13: 5824 | GB13: 5229 | GC13: 4892 | GD13: 4511 | GE13: 4200 | GF13: 3763 | GG13: 3424 | GH13: 3170 | GI13: 2850 | GJ13: 2629 | GK13: 2215 | GL13: 1820 | GM13: 1548 | GN13: 1337 | GO13: 1048 | GP13: 894 | GQ13: 673 | GR13: 636 | GS13: 561 | GT13: 455 | GU13: 400 | GV13: 336 | GW13: 288 | GX13: 330 | GY13: 34.205741 | GZ13: 2051 | HA13: 11580 | HB13: 14785 | HC13: 7590 | HD13: 3326 | HE13: 1438 | HF13: 401 | HG13: 0 | HH13: 6509 | HI13: 21403 | HJ13: 11841 | HK13: 4779 | HL13: 1733 | HM13: 459 | HN13: 54085 | HO13: 204553 | HP13: 233890 | HQ13: 152046 | HR13: 83263 | HS13: 33357 | HT13: 9908 | HU13: 202094 | HV13: 119989 | HW13: 172696 | HX13: 137541 | HY13: 75731 | HZ13: 30068 | IA13: 6617 | IB13: 188138 | IC13: 77836 | ID13: 44853 | IE13: 18270 | IF13: 6219 | IG13: 4736 | IH13: 1430 | II13: 21390 | IJ13: 150563 | IK13: 90776 | IL13: 16609 | IM13: 3613 | IN13: 2174 | IO13: 707 | IP13: 32 | IQ13: 597 | IR13: 2267 | IS13: 4257 | IT13: 8792 | IU13: 15015 | IV13: 8402 | IW13: 0 | IX13: 1025 | IY13: 5593 | IZ13: 19846 | JA13: 26785 | JB13: 32613 | JC13: 25125
... A31: 2019 | B31: 4038161 | C31: 1680144 | D31: 2004230 | E31: 2033931 | F31: 0 | G31: 21493 | H31: 21434 | I31: 21776 | J31: 21331 | K31: 20625 | L31: 20844 | M31: 20613 | N31: 20376 | O31: 20214 | P31: 20208 | Q31: 19918 | R31: 20139 | S31: 20440 | T31: 20576 | U31: 21227 | V31: 21701 | W31: 22204 | X31: 23101 | Y31: 23597 | Z31: 24256 | AA31: 25536 | AB31: 25974 | AC31: 26855 | AD31: 27514 | AE31: 28609 | AF31: 28857 | AG31: 30178 | AH31: 35875 | AI31: 54789 | AJ31: 29856 | AK31: 29664 | AL31: 29101 | AM31: 28979 | AN31: 28306 | AO31: 27976 | AP31: 27622 | AQ31: 27282 | AR31: 26887 | AS31: 26430 | AT31: 26413 | AU31: 26515 | AV31: 26626 | AW31: 26981 | AX31: 27683 | AY31: 27788 | AZ31: 28034 | BA31: 28270 | BB31: 28456 | BC31: 28589 | BD31: 28762 | BE31: 29114 | BF31: 29754 | BG31: 30772 | BH31: 31443 | BI31: 32533 | BJ31: 32765 | BK31: 32629 | BL31: 32238 | BM31: 31803 | BN31: 30952 | BO31: 30073 | BP31: 28664 | BQ31: 27198 | BR31: 25900 | BS31: 24774 | BT31: 23567 | BU31: 22442 | BV31: 21084 | BW31: 19818 | BX31: 18413 | BY31: 16848 | BZ31: 15447 | CA31: 13718 | CB31: 12149 | CC31: 10626 | CD31: 9382 | CE31: 8523 | CF31: 7876 | CG31: 7242 | CH31: 6875 | CI31: 6137 | CJ31: 5504 | CK31: 4887 | CL31: 4355 | CM31: 3843 | CN31: 3224 | CO31: 2663 | CP31: 2260 | CQ31: 1880 | CR31: 1566 | CS31: 1296 | CT31: 1059 | CU31: 840 | CV31: 666 | CW31: 525 | CX31: 440 | CY31: 329 | CZ31: 281 | DA31: 289 | DB31: 39.995026 | DC31: 0 | DD31: 23513 | DE31: 23682 | DF31: 23568 | DG31: 23233 | DH31: 22557 | DI31: 22432 | DJ31: 22114 | DK31: 21907 | DL31: 22171 | DM31: 21474 | DN31: 21620 | DO31: 21467 | DP31: 21525 | DQ31: 21852 | DR31: 22261 | DS31: 23134 | DT31: 23333 | DU31: 23994 | DV31: 25058 | DW31: 25377 | DX31: 26369 | DY31: 27135 | DZ31: 28110 | EA31: 28721 | EB31: 29240 | EC31: 29755 | ED31: 30369 | EE31: 34079 | EF31: 52926 | EG31: 25991 | EH31: 25830 | EI31: 25545 | EJ31: 25172 | EK31: 24633 | EL31: 24215 | EM31: 23839 | EN31: 23490 | EO31: 23297 | EP31: 23053 | EQ31: 23004 | ER31: 22938 | ES31: 23259 | ET31: 23737 | EU31: 24315 | EV31: 24902 | EW31: 25193 | EX31: 25629 | EY31: 25972 | EZ31: 26361 | FA31: 26902 | FB31: 27223 | FC31: 27962 | FD31: 29072 | FE31: 30203 | FF31: 31050 | FG31: 31562 | FH31: 31828 | FI31: 31774 | FJ31: 31710 | FK31: 31561 | FL31: 31058 | FM31: 30373 | FN31: 29280 | FO31: 28062 | FP31: 26909 | FQ31: 25983 | FR31: 24891 | FS31: 23674 | FT31: 22194 | FU31: 21016 | FV31: 19771 | FW31: 18320 | FX31: 16528 | FY31: 14575 | FZ31: 13064 | GA31: 11671 | GB31: 11068 | GC31: 10362 | GD31: 9798 | GE31: 9308 | GF31: 8883 | GG31: 8062 | GH31: 7366 | GI31: 6749 | GJ31: 6220 | GK31: 5416 | GL31: 4511 | GM31: 3932 | GN31: 3264 | GO31: 2790 | GP31: 2310 | GQ31: 2008 | GR31: 1653 | GS31: 1342 | GT31: 1122 | GU31: 935 | GV31: 825 | GW31: 665 | GX31: 605 | GY31: 40.813044 | GZ31: 2237 | HA31: 10479 | HB31: 20934 | HC31: 25807 | HD31: 20533 | HE31: 9188 | HF31: 3117 | HG31: 0 | HH31: 0 | HI31: 0 | HJ31: 0 | HK31: 0 | HL31: 0 | HM31: 0 | HN31: 47489 | HO31: 169886 | HP31: 213823 | HQ31: 247349 | HR31: 201006 | HS31: 86286 | HT31: 21942 | HU31: 50154 | HV31: 216722 | HW31: 220028 | HX31: 274466 | HY31: 255970 | HZ31: 136803 | IA31: 76020 | IB31: 257110 | IC31: 94882 | ID31: 36713 | IE31: 34892 | IF31: 22886 | IG31: 8916 | IH31: 3695 | II31: 261927 | IJ31: 28343 | IK31: 25282 | IL31: 24820 | IM31: 18015 | IN31: 9370 | IO31: 5116 | IP31: 1607 | IQ31: 6856 | IR31: 3885 | IS31: 3765 | IT31: 10047 | IU31: 15834 | IV31: 21249 | IW31: 0 | IX31: 0 | IY31: 0 | IZ31: 0 | JA31: 0 | JB31: 0 | JC31: 0

Sheet Residents
A1: Year | B1: Model | C1: Real
A2: 1990 | B2: =Sheet4!B2 -> 2735862 | C2: 2735868
A3: 1991 | B3: =Sheet4!B3 -> 2790350 | C3: 2794704
A4: 1992 | B4: =Sheet4!B4 -> 2849225 | C4: 2849753
A5: 1993 | B5: =Sheet4!B5 -> 2910879 | C5: 2904546
A6: 1994 | B6: =Sheet4!B6 -> 2973316 | C6: 2959351
A7: 1995 | B7: =Sheet4!B7 -> 3036851 | C7: 3013518
A8: 1996 | B8: =Sheet4!B8 -> 3100020 | C8: 3068130
A9: 1997 | B9: =Sheet4!B9 -> 3161849 | C9: 3123403
A10: 1998 | B10: =Sheet4!B10 -> 3221116 | C10: 3180019
A11: 1999 | B11: =Sheet4!B11 -> 3278084 | C11: 3229681
A12: 2000 | B12: =Sheet4!B12 -> 3331728 | C12: 3273363
A13: 2001 | B13: =Sheet4!B13 -> 3383062 | C13: 3325902
... A30: 2018 | B30: =Sheet4!B30 -> 4011088 | C30: 3994283

Sheet Non-residents
A1: Year | B1: Model | C1: Real
A2: 1990 | B2: =Sheet4!C2 -> 246389 | C2: 311264
A3: 1991 | B3: =Sheet4!C3 -> 310676 | C3: 340379
A4: 1992 | B4: =Sheet4!C4 -> 375760 | C4: 380944
A5: 1993 | B5: =Sheet4!C5 -> 439052 | C5: 408924
A6: 1994 | B6: =Sheet4!C6 -> 497903 | C6: 459698
A7: 1995 | B7: =Sheet4!C7 -> 549981 | C7: 510991
A8: 1996 | B8: =Sheet4!C8 -> 593639 | C8: 602572
A9: 1997 | B9: =Sheet4!C9 -> 628201 | C9: 672635
A10: 1998 | B10: =Sheet4!C10 -> 654152 | C10: 747195
A11: 1999 | B11: =Sheet4!C11 -> 673177 | C11: 729042
A12: 2000 | B12: =Sheet4!C12 -> 688062 | C12: 754524
A13: 2001 | B13: =Sheet4!C13 -> 702437 | C13: 812110
... A31: 2019 | B31: =Sheet4!C31 -> 1680144 | C31: 1677360
B32: 1647613
B33: 1617756

Sheet Total
A1: Year | B1: Model | C1: Real
A2: 1990 | B2: ='Non-residents'!B2+Residents!B2 -> 2982251 | C2: ='Non-residents'!C2+Residents!C2 -> 3047132
A3: 1991 | B3: ='Non-residents'!B3+Residents!B3 -> 3101026 | C3: ='Non-residents'!C3+Residents!C3 -> 3135083
A4: 1992 | B4: ='Non-residents'!B4+Residents!B4 -> 3224985 | C4: ='Non-residents'!C4+Residents!C4 -> 3230697
A5: 1993 | B5: ='Non-residents'!B5+Residents!B5 -> 3349931 | C5: ='Non-residents'!C5+Residents!C5 -> 3313470
A6: 1994 | B6: ='Non-residents'!B6+Residents!B6 -> 3471219 | C6: ='Non-residents'!C6+Residents!C6 -> 3419049
A7: 1995 | B7: ='Non-residents'!B7+Residents!B7 -> 3586832 | C7: ='Non-residents'!C7+Residents!C7 -> 3524509
A8: 1996 | B8: ='Non-residents'!B8+Residents!B8 -> 3693659 | C8: ='Non-residents'!C8+Residents!C8 -> 3670702
A9: 1997 | B9: ='Non-residents'!B9+Residents!B9 -> 3790050 | C9: ='Non-residents'!C9+Residents!C9 -> 3796038
A10: 1998 | B10: ='Non-residents'!B10+Residents!B10 -> 3875268 | C10: ='Non-residents'!C10+Residents!C10 -> 3927214
A11: 1999 | B11: ='Non-residents'!B11+Residents!B11 -> 3951261 | C11: ='Non-residents'!C11+Residents!C11 -> 3958723
A12: 2000 | B12: ='Non-residents'!B12+Residents!B12 -> 4019790 | C12: ='Non-residents'!C12+Residents!C12 -> 4027887
A13: 2001 | B13: ='Non-residents'!B13+Residents!B13 -> 4085499 | C13: ='Non-residents'!C13+Residents!C13 -> 4138012
... A30: 2018 | B30: ='Non-residents'!B30+Residents!B30 -> 5718408 | C30: ='Non-residents'!C30+Residents!C30 -> 5638676

Sheet Males
A1: Year | B1: Model | C1: Real
A2: 1990 | B2: =Sheet4!D2 -> 1386293 | C2: 1386291
A3: 1991 | B3: =Sheet4!D3 -> 1411319 | C3: 1414309 | T3: kjk
A4: 1992 | B4: =Sheet4!D4 -> 1438645 | C4: 1439064
A5: 1993 | B5: =Sheet4!D5 -> 1467789 | C5: 1464223
A6: 1994 | B6: =Sheet4!D6 -> 1497402 | C6: 1489181
A7: 1995 | B7: =Sheet4!D7 -> 1527705 | C7: 1514020
A8: 1996 | B8: =Sheet4!D8 -> 1557819 | C8: 1540018
A9: 1997 | B9: =Sheet4!D9 -> 1587484 | C9: 1565751
A10: 1998 | B10: =Sheet4!D10 -> 1615869 | C10: 1591816
A11: 1999 | B11: =Sheet4!D11 -> 1643482 | C11: 1614805
A12: 2000 | B12: =Sheet4!D12 -> 1669444 | C12: 1634667
A13: 2001 | B13: =Sheet4!D13 -> 1694024 | C13: 1658558
A14: 2002 | B14: =Sheet4!D14 -> 1717173 | C14: 1684295
A15: 2003 | B15: =Sheet4!D15 -> 1738572 | C15: 1673401
... A30: 2018 | B30: =Sheet4!D30 -> 1992306 | C30: 1955838

Sheet Females
A1: Year | B1: Model | C1: Real
A2: 1990 | B2: =Sheet4!E2 -> 1349569 | C2: 1349577
A3: 1991 | B3: =Sheet4!E3 -> 1379031 | C3: 1380398
A4: 1992 | B4: =Sheet4!E4 -> 1410580 | C4: 1410689
A5: 1993 | B5: =Sheet4!E5 -> 1443090 | C5: 1440326
A6: 1994 | B6: =Sheet4!E6 -> 1475914 | C6: 1470169
A7: 1995 | B7: =Sheet4!E7 -> 1509146 | C7: 1499504
A8: 1996 | B8: =Sheet4!E8 -> 1542201 | C8: 1528112
A9: 1997 | B9: =Sheet4!E9 -> 1574365 | C9: 1557652
A10: 1998 | B10: =Sheet4!E10 -> 1605247 | C10: 1588202
A11: 1999 | B11: =Sheet4!E11 -> 1634602 | C11: 1614877
A12: 2000 | B12: =Sheet4!E12 -> 1662284 | C12: 1638696
A13: 2001 | B13: =Sheet4!E13 -> 1689038 | C13: 1667344
... A30: 2018 | B30: =Sheet4!E30 -> 2018782 | C30: 2038445
G40: 1349577 | H40: 1380398 | I40: 1410689 | J40: 1440326 | K40: 1470169 | L40: 1499504 | M40: 1528112 | N40: 1557652 | O40: 1588202 | P40: 1614877 | Q40: 1638696 | R40: 1667344 | S40: 1698649 | T40: 1693490 | U40: 1718235 | V40: 1746675 | W40: 1777652 | X40: 1807605 | Y40: 1839667 | Z40: 1889144 | AA40: 1910588 | AB40: 1921081 | AC40: 1938159 | AD40: 1953247 | AE40: 1968329 | AF40: 1986062 | AG40: 2004033 | AH40: 2022251 | AI40: 2038445

Sheet Males AverageAge
A1: Year | B1: Model | C1: Real
A2: 1990 | B2: =Sheet4!DB2 -> 30.192 | C2: 30.164704
A3: 1991 | B3: =Sheet4!DB3 -> 30.449647 | C3: 30.363229
A4: 1992 | B4: =Sheet4!DB4 -> 30.704028 | C4: 30.606236
A5: 1993 | B5: =Sheet4!DB5 -> 30.955403 | C5: 30.845657
A6: 1994 | B6: =Sheet4!DB6 -> 31.212742 | C6: 31.103282
A7: 1995 | B7: =Sheet4!DB7 -> 31.467139 | C7: 31.342935
A8: 1996 | B8: =Sheet4!DB8 -> 31.742883 | C8: 31.591553
A9: 1997 | B9: =Sheet4!DB9 -> 32.027717 | C9: 31.854188
A10: 1998 | B10: =Sheet4!DB10 -> 32.329476 | C10: 32.141766
A11: 1999 | B11: =Sheet4!DB11 -> 32.642218 | C11: 32.479414
A12: 2000 | B12: =Sheet4!DB12 -> 32.981187 | C12: 32.810835
A13: 2001 | B13: =Sheet4!DB13 -> 33.33075 | C13: 33.116735
... A30: 2018 | B30: =Sheet4!DB30 -> 39.660431 | C30: 39.306589

Sheet Females AverageAge
A1: Year | B1: Model | C1: Real
A2: 1990 | B2: =Sheet4!GY2 -> 31.205502 | C2: 31.185489
A3: 1991 | B3: =Sheet4!GY3 -> 31.404213 | C3: 31.384138
A4: 1992 | B4: =Sheet4!GY4 -> 31.614127 | C4: 31.612225
A5: 1993 | B5: =Sheet4!GY5 -> 31.843842 | C5: 31.858962
A6: 1994 | B6: =Sheet4!GY6 -> 32.083298 | C6: 32.113603
A7: 1995 | B7: =Sheet4!GY7 -> 32.333903 | C7: 32.368042
A8: 1996 | B8: =Sheet4!GY8 -> 32.603219 | C8: 32.625916
A9: 1997 | B9: =Sheet4!GY9 -> 32.891863 | C9: 32.897524
A10: 1998 | B10: =Sheet4!GY10 -> 33.194446 | C10: 33.17889
A11: 1999 | B11: =Sheet4!GY11 -> 33.516755 | C11: 33.527429
A12: 2000 | B12: =Sheet4!GY12 -> 33.862126 | C12: 33.867201
A13: 2001 | B13: =Sheet4!GY13 -> 34.205741 | C13: 34.18947
... A30: 2018 | B30: =Sheet4!GY30 -> 40.498155 | C30: 40.523912

Sheet SM
A1: Year | B1: Model | C1: Real
A2: 1990 | B2: =Sheet4!IB2+Sheet4!IC2+Sheet4!ID2+Sheet4!IE2+Sheet4!IF2+Sheet4!IG2+Sheet4!IH2 -> 308400 | C2: 308400 | D2: =ABS(C2-B2) -> 0
A3: 1991 | B3: =Sheet4!IB3+Sheet4!IC3+Sheet4!ID3+Sheet4!IE3+Sheet4!IF3+Sheet4!IG3+Sheet4!IH3 -> 307480 | C3: 302300 | D3: =ABS(C3-B3) -> 5180
A4: 1992 | B4: =Sheet4!IB4+Sheet4!IC4+Sheet4!ID4+Sheet4!IE4+Sheet4!IF4+Sheet4!IG4+Sheet4!IH4 -> 308059 | C4: 312500 | D4: =ABS(C4-B4) -> 4441
A5: 1993 | B5: =Sheet4!IB5+Sheet4!IC5+Sheet4!ID5+Sheet4!IE5+Sheet4!IF5+Sheet4!IG5+Sheet4!IH5 -> 309995 | C5: 316100 | D5: =ABS(C5-B5) -> 6105
A6: 1994 | B6: =Sheet4!IB6+Sheet4!IC6+Sheet4!ID6+Sheet4!IE6+Sheet4!IF6+Sheet4!IG6+Sheet4!IH6 -> 312748 | C6: 313600 | D6: =ABS(C6-B6) -> 852
A7: 1995 | B7: =Sheet4!IB7+Sheet4!IC7+Sheet4!ID7+Sheet4!IE7+Sheet4!IF7+Sheet4!IG7+Sheet4!IH7 -> 316890 | C7: 313000 | D7: =ABS(C7-B7) -> 3890
A8: 1996 | B8: =Sheet4!IB8+Sheet4!IC8+Sheet4!ID8+Sheet4!IE8+Sheet4!IF8+Sheet4!IG8+Sheet4!IH8 -> 320705 | C8: 297300 | D8: =ABS(C8-B8) -> 23405
A9: 1997 | B9: =Sheet4!IB9+Sheet4!IC9+Sheet4!ID9+Sheet4!IE9+Sheet4!IF9+Sheet4!IG9+Sheet4!IH9 -> 324931 | C9: 313600 | D9: =ABS(C9-B9) -> 11331
A10: 1998 | B10: =Sheet4!IB10+Sheet4!IC10+Sheet4!ID10+Sheet4!IE10+Sheet4!IF10+Sheet4!IG10+Sheet4!IH10 -> 328931 | C10: 306100 | D10: =ABS(C10-B10) -> 22831
A11: 1999 | B11: =Sheet4!IB11+Sheet4!IC11+Sheet4!ID11+Sheet4!IE11+Sheet4!IF11+Sheet4!IG11+Sheet4!IH11 -> 333029 | C11: 308500 | D11: =ABS(C11-B11) -> 24529
A12: 2000 | B12: =Sheet4!IB12+Sheet4!IC12+Sheet4!ID12+Sheet4!IE12+Sheet4!IF12+Sheet4!IG12+Sheet4!IH12 -> 336998 | C12: 303100 | D12: =ABS(C12-B12) -> 33898
A13: 2001 | B13: =Sheet4!IB13+Sheet4!IC13+Sheet4!ID13+Sheet4!IE13+Sheet4!IF13+Sheet4!IG13+Sheet4!IH13 -> 341482 | C13: 304900 | D13: =ABS(C13-B13) -> 36582
... A30: 2018 | B30: =Sheet4!IB30+Sheet4!IC30+Sheet4!ID30+Sheet4!IE30+Sheet4!IF30+Sheet4!IG30+Sheet4!IH30 -> 460389 | C30: 414400 | D30: =ABS(C30-B30) -> 45989
D31: =SUM(D2:D30) -> 837191

Sheet MM
A1: Year | B1: Model | C1: Real
A2: 1990 | B2: =Sheet4!HN2+Sheet4!HO2+Sheet4!HP2+Sheet4!HQ2+Sheet4!HR2+Sheet4!HS2+Sheet4!HT2 -> 600548 | C2: 586400 | D2: =ABS(C2-B2) -> 14148
A3: 1991 | B3: =Sheet4!HN3+Sheet4!HO3+Sheet4!HP3+Sheet4!HQ3+Sheet4!HR3+Sheet4!HS3+Sheet4!HT3 -> 617424 | C3: 621300 | D3: =ABS(C3-B3) -> 3876
A4: 1992 | B4: =Sheet4!HN4+Sheet4!HO4+Sheet4!HP4+Sheet4!HQ4+Sheet4!HR4+Sheet4!HS4+Sheet4!HT4 -> 634406 | C4: 633200 | D4: =ABS(C4-B4) -> 1206
A5: 1993 | B5: =Sheet4!HN5+Sheet4!HO5+Sheet4!HP5+Sheet4!HQ5+Sheet4!HR5+Sheet4!HS5+Sheet4!HT5 -> 650929 | C5: 657300 | D5: =ABS(C5-B5) -> 6371
A6: 1994 | B6: =Sheet4!HN6+Sheet4!HO6+Sheet4!HP6+Sheet4!HQ6+Sheet4!HR6+Sheet4!HS6+Sheet4!HT6 -> 667003 | C6: 674700 | D6: =ABS(C6-B6) -> 7697
A7: 1995 | B7: =Sheet4!HN7+Sheet4!HO7+Sheet4!HP7+Sheet4!HQ7+Sheet4!HR7+Sheet4!HS7+Sheet4!HT7 -> 682017 | C7: 692100 | D7: =ABS(C7-B7) -> 10083
A8: 1996 | B8: =Sheet4!HN8+Sheet4!HO8+Sheet4!HP8+Sheet4!HQ8+Sheet4!HR8+Sheet4!HS8+Sheet4!HT8 -> 697473 | C8: 716800 | D8: =ABS(C8-B8) -> 19327
A9: 1997 | B9: =Sheet4!HN9+Sheet4!HO9+Sheet4!HP9+Sheet4!HQ9+Sheet4!HR9+Sheet4!HS9+Sheet4!HT9 -> 712489 | C9: 736600 | D9: =ABS(C9-B9) -> 24111
A10: 1998 | B10: =Sheet4!HN10+Sheet4!HO10+Sheet4!HP10+Sheet4!HQ10+Sheet4!HR10+Sheet4!HS10+Sheet4!HT10 -> 727376 | C10: 750500 | D10: =ABS(C10-B10) -> 23124
A11: 1999 | B11: =Sheet4!HN11+Sheet4!HO11+Sheet4!HP11+Sheet4!HQ11+Sheet4!HR11+Sheet4!HS11+Sheet4!HT11 -> 741870 | C11: 768500 | D11: =ABS(C11-B11) -> 26630
A12: 2000 | B12: =Sheet4!HN12+Sheet4!HO12+Sheet4!HP12+Sheet4!HQ12+Sheet4!HR12+Sheet4!HS12+Sheet4!HT12 -> 756668 | C12: 770800 | D12: =ABS(C12-B12) -> 14132
A13: 2001 | B13: =Sheet4!HN13+Sheet4!HO13+Sheet4!HP13+Sheet4!HQ13+Sheet4!HR13+Sheet4!HS13+Sheet4!HT13 -> 771102 | C13: 792700 | D13: =ABS(C13-B13) -> 21598
... A30: 2018 | B30: =Sheet4!HN30+Sheet4!HO30+Sheet4!HP30+Sheet4!HQ30+Sheet4!HR30+Sheet4!HS30+Sheet4!HT30 -> 978942 | C30: 1025100 | D30: =ABS(C30-B30) -> 46158
D31: =SUM(D2:D30) -> 846947

Sheet WM
A1: Year | B1: Model | C1: Real
A2: 1990 | B2: =Sheet4!IP2+Sheet4!IQ2+Sheet4!IR2+Sheet4!IS2+Sheet4!IT2+Sheet4!IU2+Sheet4!IV2 -> 25701 | C2: 26000 | D2: =ABS(C2-B2) -> 299
A3: 1991 | B3: =Sheet4!IP3+Sheet4!IQ3+Sheet4!IR3+Sheet4!IS3+Sheet4!IT3+Sheet4!IU3+Sheet4!IV3 -> 27789 | C3: 20200 | D3: =ABS(C3-B3) -> 7589
A4: 1992 | B4: =Sheet4!IP4+Sheet4!IQ4+Sheet4!IR4+Sheet4!IS4+Sheet4!IT4+Sheet4!IU4+Sheet4!IV4 -> 29413 | C4: 22400 | D4: =ABS(C4-B4) -> 7013
A5: 1993 | B5: =Sheet4!IP5+Sheet4!IQ5+Sheet4!IR5+Sheet4!IS5+Sheet4!IT5+Sheet4!IU5+Sheet4!IV5 -> 30965 | C5: 20700 | D5: =ABS(C5-B5) -> 10265
